Workbook
Name Ano_Anterior: 'Tab Dinamicas'!$G$39:$K$50
Name Anos: Listas!$C$2:$C$5
Name Foto_Dinamica: INDEX(Fotos,MATCH('Tab Dinamicas'!$B$19,Gerentes,0))
Name Fotos: Listas!$F$2:$F$4
Name Gerentes: Listas!$E$2:$E$4
Name Mês_Anterior: 'Tab Dinamicas'!$B$39:$D$50
Name Meses: Listas!$A$2:$A$13
Name SegmentaçãodeDados_Anos: #N/A
Name SegmentaçãodeDados_Meses: #N/A
Name SegmentaçãodeDados_Vendedor2: #N/A

Sheet Tab Dinamicas
A3: Anos | B3: 2016
A4: Meses | B4: set
A6: Gerentes | B6: Soma de Total | C6: =LEFT(B19,1) -> S | D6: Gerentes | E6: Contagem de Total | G6: Gerente | H6: % R$ | I6: % Cont | J6: Maior R$ | K6: Maior Cont | L6: Média R$ | M6: Média Cont. | N6: Mês Anterior | O6: Ano Anterior
A7: Silvane | B7: 3853 | C7: =_xlfn.RANK.EQ(GETPIVOTDATA("Total",$A$6),B14:B16)&"º" -> 3º | D7: Silvane | E7: 9 | G7: =B19 -> Silvane | H7: =GETPIVOTDATA("Total",$A$6)/GETPIVOTDATA("Total",$A$13) -> 0.27287535 | I7: =GETPIVOTDATA("Total",$D$6)/GETPIVOTDATA("Total",$D$13) -> 0.3 | J7: =MAX(B14:B16) -> 5549 | K7: =MAX(E14:E16) -> 11 | L7: =AVERAGE(B22:B33) -> 5542.0833 | M7: =AVERAGE(E22:E33) -> 11.75 | N7: =INDEX(Mês_Anterior, MATCH(B4,Meses,0), MATCH(VALUE(B3),Anos,0)) -> -0.35643895 | O7: =INDEX(Ano_Anterior, MATCH(B4,Meses,0), MATCH(VALUE(B3),Anos,0)) -> 3853
A8: Total Geral | B8: 3853 | C8: =INDEX(Fotos,MATCH('Tab Dinamicas'!$B$19,Gerentes,0)) -> 0 | D8: Total Geral | E8: 9 | H8: =1-H7 -> 0.72712465 | I8: =1-I7 -> 0.7 | J8: =J7 -> 5549 | K8: =+K7 -> 11 | L8: =J7 -> 5549 | M8: =+K7 -> 11
J9: =GETPIVOTDATA("Total",$A$6) -> 3853 | K9: =GETPIVOTDATA("Total",$D$6) -> 9 | L9: =MIN(L7,L8) -> 5542.0833 | M9: =MIN(M7,M8) -> 11
J10: =J7-J9 -> 1696 | K10: =+K8-K9 -> 2 | L10: =+L9*0.8% -> 44.336667 | M10: =+M9*0.8% -> 0.088
L11: =+L8-L9-L10 -> -37.42 | M11: =+M8-M9-M10 -> -0.088
A13: Gerentes | B13: Vendas R$ | D13: Gerentes | E13: Contagem de Total | G13: Gerentes | H13: Soma de Total | J13: Gerentes | K13: Contagem de Total
A14: Wellington | B14: 5549 | D14: Wellington | E14: 11 | G14: Silvane | H14: 0.27287535 | J14: Silvane | K14: 0.3
A15: Barbara | B15: 4718 | D15: Barbara | E15: 10 | G15: Wellington | H15: 0.39298867 | J15: Wellington | K15: 0.36666667
A16: Silvane | B16: 3853 | D16: Silvane | E16: 9 | G16: Barbara | H16: 0.33413598 | J16: Barbara | K16: 0.33333333
A17: Total Geral | B17: 14120 | D17: Total Geral | E17: 30 | G17: Total Geral | H17: 1 | J17: Total Geral | K17: 1
A19: Gerentes | B19: Silvane
A21: Meses | B21: Vendas R$ | C21: Contagem | D21: Gerentes | E21: Contagem de Total | G21: Gerentes | H21: Soma de Total | J21: Gerentes | K21: Contagem de Total
A22: jan | B22: 5675 | C22: 11 | D22: jan | E22: 11 | G22: jan | H22: 0.08533193 | J22: jan | K22: 0.078014184
A23: fev | B23: 6209 | C23: 13 | D23: fev | E23: 13 | G23: fev | H23: 0.093361401 | J23: fev | K23: 0.092198582
A24: mar | B24: 6386 | C24: 14 | D24: mar | E24: 14 | G24: mar | H24: 0.096022855 | J24: mar | K24: 0.09929078
A25: abr | B25: 7987 | C25: 18 | D25: abr | E25: 18 | G25: abr | H25: 0.12009623 | J25: abr | K25: 0.12765957
A26: mai | B26: 6064 | C26: 11 | D26: mai | E26: 11 | G26: mai | H26: 0.091181114 | J26: mai | K26: 0.078014184
A27: jun | B27: 4232 | C27: 10 | D27: jun | E27: 10 | G27: jun | H27: 0.063634313 | J27: jun | K27: 0.070921986
A28: jul | B28: 2842 | C28: 7 | D28: jul | E28: 7 | G28: jul | H28: 0.042733629 | J28: jul | K28: 0.04964539
A29: ago | B29: 5987 | C29: 14 | D29: ago | E29: 14 | G29: ago | H29: 0.090023307 | J29: ago | K29: 0.09929078
A30: set | B30: 3853 | C30: 9 | D30: set | E30: 9 | G30: set | H30: 0.057935494 | J30: set | K30: 0.063829787
A31: out | B31: 5308 | C31: 10 | D31: out | E31: 10 | G31: out | H31: 0.079813548 | J31: out | K31: 0.070921986
A32: nov | B32: 4416 | C32: 9 | D32: nov | E32: 9 | G32: nov | H32: 0.066401022 | J32: nov | K32: 0.063829787
A33: dez | B33: 7546 | C33: 15 | D33: dez | E33: 15 | G33: dez | H33: 0.11346515 | J33: dez | K33: 0.10638298
D34: Total Geral | E34: 141 | G34: Total Geral | H34: 1 | J34: Total Geral | K34: 1
A37: MoM % | B37: Anos | F37: Meses | G37: Vendas R$ | H37: YoY %
A38: Meses | B38: 2016 | C38: 2017 | D38: 2018 | F38: 2016 | G38: 66505
A39: jan | F39: jan | G39: 5675
A40: fev | B40: 0.094096916 | C40: 0.23606999 | D40: 0.084389651 | F40: fev | G40: 6209
A41: mar | B41: 0.028507006 | C41: 0.13850174 | D41: -0.1378703 | F41: mar | G41: 6386
A42: abr | B42: 0.25070467 | C42: -0.33856159 | D42: 0.62202823 | F42: abr | G42: 7987
A43: mai | B43: -0.24076625 | C43: 0.68710237 | D43: -0.62120692 | F43: mai | G43: 6064
A44: jun | B44: -0.30211082 | C44: 0.069763456 | D44: 0.49153567 | F44: jun | G44: 4232
A45: jul | B45: -0.32844991 | C45: -0.7106233 | D45: -0.12363194 | F45: jul | G45: 2842
A46: ago | B46: 1.1066151 | C46: 1.4130676 | D46: 0.012719704 | F46: ago | G46: 5987
A47: set | B47: -0.35643895 | C47: 0.27810922 | D47: 0.20712491 | F47: set | G47: 3853
A48: out | B48: 0.37762782 | C48: -0.59820467 | F48: out | G48: 5308
...

Sheet Base
A1: Turma | B1: Vendedor | C1: Treinamento | D1: Data Início | E1: Data Término | F1: Cliente | G1: Instrutor | H1: Feedback | I1: Alunos | J1: Valor | K1: Total
A2: 4355 | B2: Renato | C2: Outlook 2013 | D2: 42370.333 | E2: 42383.5 | F2: Pessoa Jurídica | G2: Douglas | H2: 4 | I2: 9 | J2: 41 | K2: =+Treinamentos[[#This Row],[Alunos]]*Treinamentos[[#This Row],[Valor]] -> 369
A3: 4356 | B3: Vanessa | C3: Access VBA 2013 | D3: 42370.333 | E3: 42383.5 | F3: Pessoa Jurídica | G3: Roberto | H3: 2 | I3: 11 | J3: 62 | K3: =+Treinamentos[[#This Row],[Alunos]]*Treinamentos[[#This Row],[Valor]] -> 682
A4: 4357 | B4: Rodrigo | C4: Excel Básico 2013 | D4: 42371.375 | E4: 42376.75 | F4: Pessoa Jurídica | G4: Caio | H4: 2 | I4: 11 | J4: 33 | K4: =+Treinamentos[[#This Row],[Alunos]]*Treinamentos[[#This Row],[Valor]] -> 363
A5: 4358 | B5: Roberto | C5: Word VBA 2013 | D5: 42373.792 | E5: 42384.958 | F5: Pessoa Física | G5: Sérgio | H5: 3 | I5: 12 | J5: 47 | K5: =+Treinamentos[[#This Row],[Alunos]]*Treinamentos[[#This Row],[Valor]] -> 564
A6: 4359 | B6: Rodrigo | C6: Outlook VBA 2013 | D6: 42373.792 | E6: 42384.958 | F6: Pessoa Jurídica | G6: Sandra | H6: 2 | I6: 11 | J6: 47 | K6: =+Treinamentos[[#This Row],[Alunos]]*Treinamentos[[#This Row],[Valor]] -> 517
A7: 4360 | B7: Adriana | C7: Excel VBA avançado 2013 | D7: 42374.792 | E7: 42387.958 | F7: Pessoa Jurídica | G7: Rosana | H7: 5 | I7: 11 | J7: 73 | K7: =+Treinamentos[[#This Row],[Alunos]]*Treinamentos[[#This Row],[Valor]] -> 803
A8: 4361 | B8: Katia | C8: Excel Avançado 2013 | D8: 42375.583 | E8: 42388.75 | F8: Pessoa Jurídica | G8: Caio | H8: 5 | I8: 10 | J8: 42 | K8: =+Treinamentos[[#This Row],[Alunos]]*Treinamentos[[#This Row],[Valor]] -> 420
A9: 4362 | B9: Priscila | C9: Excel VBA iniciante 2013 | D9: 42375.583 | E9: 42388.75 | F9: Pessoa Jurídica | G9: Humberto | H9: 4 | I9: 10 | J9: 61 | K9: =+Treinamentos[[#This Row],[Alunos]]*Treinamentos[[#This Row],[Valor]] -> 610
A10: 4363 | B10: Renato | C10: Outlook VBA 2013 | D10: 42375.583 | E10: 42388.75 | F10: Pessoa Jurídica | G10: Paulo | H10: 4 | I10: 9 | J10: 47 | K10: =+Treinamentos[[#This Row],[Alunos]]*Treinamentos[[#This Row],[Valor]] -> 423
A11: 4364 | B11: Vanessa | C11: Word VBA 2013 | D11: 42377.333 | E11: 42390.5 | F11: Pessoa Jurídica | G11: Sérgio | H11: 5 | I11: 9 | J11: 47 | K11: =+Treinamentos[[#This Row],[Alunos]]*Treinamentos[[#This Row],[Valor]] -> 423
A12: 4365 | B12: Rodrigo | C12: Excel Avançado 2013 | D12: 42378.375 | E12: 42383.75 | F12: Pessoa Física | G12: Fernando | H12: 5 | I12: 10 | J12: 42 | K12: =+Treinamentos[[#This Row],[Alunos]]*Treinamentos[[#This Row],[Valor]] -> 420
A13: 4366 | B13: Priscila | C13: PowerPoint 2013 | D13: 42378.375 | E13: 42383.75 | F13: Pessoa Física | G13: Roberto | H13: 3 | I13: 10 | J13: 47 | K13: =+Treinamentos[[#This Row],[Alunos]]*Treinamentos[[#This Row],[Valor]] -> 470
... A107: 4460 | B107: Roberto | C107: Excel Avançado 2013 | D107: 42454.333 | E107: 42467.5 | F107: Pessoa Física | G107: Fernando | H107: 2 | I107: 9 | J107: 42 | K107: =+Treinamentos[[#This Row],[Alunos]]*Treinamentos[[#This Row],[Valor]] -> 378
A108: 4461 | B108: Katia | C108: Excel VBA iniciante 2013 | D108: 42454.333 | E108: 42467.5 | F108: Pessoa Física | G108: Paulo | I108: 11 | J108: 61 | K108: =+Treinamentos[[#This Row],[Alunos]]*Treinamentos[[#This Row],[Valor]] -> 671
A109: 4462 | B109: Rodrigo | C109: Access 2013 | D109: 42454.333 | E109: 42467.5 | F109: Pessoa Física | G109: Fernando | H109: 2 | I109: 9 | J109: 52 | K109: =+Treinamentos[[#This Row],[Alunos]]*Treinamentos[[#This Row],[Valor]] -> 468
A110: 4463 | B110: Adriana | C110: Outlook 2013 | D110: 42454.333 | E110: 42467.5 | F110: Pessoa Física | G110: Sérgio | H110: 2 | I110: 9 | J110: 41 | K110: =+Treinamentos[[#This Row],[Alunos]]*Treinamentos[[#This Row],[Valor]] -> 369
A111: 4464 | B111: Renato | C111: Excel VBA avançado 2013 | D111: 42457.792 | E111: 42468.958 | F111: Pessoa Jurídica | G111: Sandra | H111: 3 | I111: 9 | J111: 73 | K111: =+Treinamentos[[#This Row],[Alunos]]*Treinamentos[[#This Row],[Valor]] -> 657
A112: 4465 | B112: Roberto | C112: Access 2013 | D112: 42458.792 | E112: 42471.958 | F112: Pessoa Física | G112: Humberto | H112: 5 | I112: 8 | J112: 52 | K112: =+Treinamentos[[#This Row],[Alunos]]*Treinamentos[[#This Row],[Valor]] -> 416
A113: 4466 | B113: Vanessa | C113: DashBoard 2013 | D113: 42459.583 | E113: 42472.75 | F113: Pessoa Jurídica | G113: Caio | H113: 5 | I113: 9 | J113: 31 | K113: =+Treinamentos[[#This Row],[Alunos]]*Treinamentos[[#This Row],[Valor]] -> 279
A114: 4467 | B114: Mirian | C114: Excel VBA iniciante 2013 | D114: 42459.583 | E114: 42472.75 | F114: Pessoa Física | G114: Rosana | H114: 4 | I114: 8 | J114: 61 | K114: =+Treinamentos[[#This Row],[Alunos]]*Treinamentos[[#This Row],[Valor]] -> 488
A115: 4468 | B115: Rodrigo | C115: Access 2013 | D115: 42459.583 | E115: 42472.75 | F115: Pessoa Jurídica | G115: Caio | H115: 2 | I115: 11 | J115: 52 | K115: =+Treinamentos[[#This Row],[Alunos]]*Treinamentos[[#This Row],[Valor]] -> 572
A116: 4469 | B116: Mirian | C116: Excel VBA iniciante 2013 | D116: 42460.375 | E116: 42466.75 | F116: Pessoa Jurídica | G116: Paulo | H116: 5 | I116: 12 | J116: 61 | K116: =+Treinamentos[[#This Row],[Alunos]]*Treinamentos[[#This Row],[Valor]] -> 732
A117: 4470 | B117: Murilo | C117: Excel VBA iniciante 2013 | D117: 42461.333 | E117: 42474.5 | F117: Pessoa Jurídica | G117: Caio | H117: 3 | I117: 8 | J117: 61 | K117: =+Treinamentos[[#This Row],[Alunos]]*Treinamentos[[#This Row],[Valor]] -> 488
A118: 4471 | B118: Roberto | C118: DashBoard 2013 | D118: 42461.333 | E118: 42474.5 | F118: Pessoa Física | G118: Sérgio | H118: 2 | I118: 12 | J118: 31 | K118: =+Treinamentos[[#This Row],[Alunos]]*Treinamentos[[#This Row],[Valor]] -> 372
A119: 4472 | B119: Renato | C119: Excel VBA avançado 2013 | D119: 42461.333 | E119: 42474.5 | F119: Pessoa Jurídica | G119: Caio | H119: 2 | I119: 12 | J119: 73 | K119: =+Treinamentos[[#This Row],[Alunos]]*Treinamentos[[#This Row],[Valor]] -> 876
A120: 4473 | B120: Mirian | C120: DashBoard 2013 | D120: 42462.375 | E120: 42467.75 | F120: Pessoa Jurídica | G120: Fernando | H120: 3 | I120: 9 | J120: 31 | K120: =+Treinamentos[[#This Row],[Alunos]]*Treinamentos[[#This Row],[Valor]] -> 279
... A223: 4576 | B223: Rodrigo | C223: Excel Avançado 2016 | D223: 42539.375 | E223: 42544.75 | F223: Pessoa Física | G223: Sandra | H223: 4 | I223: 9 | J223: 43 | K223: =+Treinamentos[[#This Row],[Alunos]]*Treinamentos[[#This Row],[Valor]] -> 387
A224: 4577 | B224: Roberto | C224: DashBoard 2016 | D224: 42541.792 | E224: 42552.958 | F224: Pessoa Jurídica | G224: Caio | I224: 11 | J224: 32 | K224: =+Treinamentos[[#This Row],[Alunos]]*Treinamentos[[#This Row],[Valor]] -> 352
A225: 4578 | B225: Katia | C225: Excel Básico 2016 | D225: 42541.792 | E225: 42552.958 | F225: Pessoa Jurídica | G225: José | H225: 2 | I225: 11 | J225: 35 | K225: =+Treinamentos[[#This Row],[Alunos]]*Treinamentos[[#This Row],[Valor]] -> 385
A226: 4579 | B226: Roberto | C226: Access 2016 | D226: 42542.792 | E226: 42555.958 | F226: Pessoa Física | G226: Joaquim | H226: 5 | I226: 12 | J226: 53 | K226: =+Treinamentos[[#This Row],[Alunos]]*Treinamentos[[#This Row],[Valor]] -> 636
A227: 4580 | B227: Adriana | C227: Excel Avançado 2016 | D227: 42543.583 | E227: 42556.75 | F227: Pessoa Física | G227: Fernando | H227: 2 | I227: 11 | J227: 43 | K227: =+Treinamentos[[#This Row],[Alunos]]*Treinamentos[[#This Row],[Valor]] -> 473
A228: 4581 | B228: Roberto | C228: Outlook 2016 | D228: 42544.375 | E228: 42550.75 | F228: Pessoa Jurídica | G228: Paulo | H228: 5 | I228: 12 | J228: 42 | K228: =+Treinamentos[[#This Row],[Alunos]]*Treinamentos[[#This Row],[Valor]] -> 504
A229: 4582 | B229: Mirian | C229: Outlook 2016 | D229: 42545.333 | E229: 42558.5 | F229: Pessoa Física | G229: Fernando | H229: 2 | I229: 12 | J229: 42 | K229: =+Treinamentos[[#This Row],[Alunos]]*Treinamentos[[#This Row],[Valor]] -> 504
A230: 4583 | B230: Priscila | C230: PowerPoint 2016 | D230: 42546.375 | E230: 42551.75 | F230: Pessoa Física | G230: Fernando | H230: 5 | I230: 8 | J230: 48 | K230: =+Treinamentos[[#This Row],[Alunos]]*Treinamentos[[#This Row],[Valor]] -> 384
A231: 4584 | B231: Mirian | C231: Word VBA 2016 | D231: 42548.792 | E231: 42559.958 | F231: Pessoa Jurídica | G231: Humberto | H231: 4 | I231: 8 | J231: 48 | K231: =+Treinamentos[[#This Row],[Alunos]]*Treinamentos[[#This Row],[Valor]] -> 384
A232: 4585 | B232: Katia | C232: Access 2016 | D232: 42548.792 | E232: 42559.958 | F232: Pessoa Física | G232: Paulo | H232: 4 | I232: 9 | J232: 53 | K232: =+Treinamentos[[#This Row],[Alunos]]*Treinamentos[[#This Row],[Valor]] -> 477
A233: 4586 | B233: Vanessa | C233: DashBoard 2016 | D233: 42549.792 | E233: 42562.958 | F233: Pessoa Jurídica | G233: Sérgio | H233: 2 | I233: 8 | J233: 32 | K233: =+Treinamentos[[#This Row],[Alunos]]*Treinamentos[[#This Row],[Valor]] -> 256
A234: 4587 | B234: Vanessa | C234: DashBoard 2016 | D234: 42550.583 | E234: 42563.75 | F234: Pessoa Jurídica | G234: Sandra | H234: 3 | I234: 11 | J234: 32 | K234: =+Treinamentos[[#This Row],[Alunos]]*Treinamentos[[#This Row],[Valor]] -> 352
A235: 4588 | B235: Priscila | C235: Excel Básico 2016 | D235: 42551.375 | E235: 42557.75 | F235: Pessoa Física | G235: Paulo | H235: 2 | I235: 12 | J235: 35 | K235: =+Treinamentos[[#This Row],[Alunos]]*Treinamentos[[#This Row],[Valor]] -> 420
...

Sheet Listas
A1: Meses | C1: Anos | E1: Gerentes
A2: Jan | C2: 2016 | E2: Barbara
A3: Fev | C3: 2017 | E3: Silvane
A4: Mar | C4: 2018 | E4: Wellington
A5: Abr | C5: 2019
A6: Mai
A7: Jun
A8: Jul
A9: Ago
A10: Set
A11: Out
A12: Nov
A13: Dez

Sheet Dashboard
D3: Total R$ | F3: Contagem | H3: Mês Anterior | J3: Ano Anterior
D4: =GETPIVOTDATA("Total",'Tab Dinamicas'!$A$6) -> 3853 | F4: =GETPIVOTDATA("Total",'Tab Dinamicas'!$D$6) -> 9 | H4: =IFERROR('Tab Dinamicas'!N7,"") -> -0.35643895 | J4: =IFERROR('Tab Dinamicas'!O7,"") -> 3853
